// handles global errors and rejections
import { Readable } from 'stream'
export default {
  'global error'() {
    const rs = new Readable({
      read() {
        throw new Error('Global Error')
      },
    })
    rs.pipe(process.stdout)
  },
  async 'global rejection'() {
    setTimeout(async () => {
      throw new Error('Promise Error')
    }, 1)
    await new Promise(r => setTimeout(r, 100))
  },
}

/* stdout */
 test/temp/test.js
  âœ—  global error
  | Error: Global Error
  |     at Readable.read [as _read] (/test/temp/test.js:6:15)
  âœ—  global rejection
  | Error: Promise Error
  |     at Timeout.setTimeout [as _onTimeout] (/test/temp/test.js:13:13)

test/temp/test.js > global error
  Error: Global Error
      at Readable.read [as _read] (/test/temp/test.js:6:15)

test/temp/test.js > global rejection
  Error: Promise Error
      at Timeout.setTimeout [as _onTimeout] (/test/temp/test.js:13:13)

ðŸ¦…  Executed 2 tests: 2 errors.
/**/

// catches persistent context errors
export default {
  persistentContext: class {
    _init() {
      throw new Error('Init error')
    }
  },
  'persistent context error'() {
  },
}

/* stdout */
 test/temp/test.js
  âœ—  persistent context error
  | Error: Persistent context failed to evaluate: Init error
  |     at persistentContext._init (/test/temp/test.js:4:13)

test/temp/test.js > persistent context error
  Error: Persistent context failed to evaluate: Init error
      at persistentContext._init (/test/temp/test.js:4:13)

ðŸ¦…  Executed 1 test: 1 error.
/**/

// notifies of an error in persistent context destroy
export const destroy = {
  persistentContext: class {
    _destroy() {
      throw new Error('Destroy error')
    }
  },
  'destroy error'() {
  },
}

export const ok = { continue() {} }

/* stdout */
 test/temp/test.js
   destroy
    âœ“  destroy error
Error: Destroy error
    at persistentContext._destroy (/test/temp/test.js:4:13)
   ok
    âœ“  continue

ðŸ¦…  Executed 2 tests.
/**/
